Workbook

Sheet Data Comparison
A1: Max of Employees | B1: Data | W1: ID | X1: Class_ID | Y1: Name | Z1: Pay_Name | AA1: Class_Name | AB1: Time_Present | AC1: Pay_Present | AD1: Class_Present | AE1: Source
A2: Period_End | B2: Pay Data | C2: Time Data
A3: 43841 | B3: 1
A4: 43855 | B4: 1
A5: 43859 | C5: 1
A6: 43869 | B6: 1
A7: 43873 | C7: 1
A8: 43883 | B8: 1
A9: 43887 | C9: 1
A10: 43897 | B10: 1
A11: 43901 | C11: 1
A12: 43911 | B12: 1
A13: 43915 | C13: 1
A14: 43999 | C14: 1
A15: 44009 | B15: 1
A16: 44013 | C16: 1
A17: 44023 | B17: 1
A18: 44027 | C18: 1
A19: 44037 | B19: 1
A20: 44041 | C20: 1
A21: 44051 | B21: 1
A22: 44055 | C22: 1
A23: 44065 | B23: 1
A24: 44069 | C24: 1
A25: 44079 | B25: 1
A26: 44083 | C26: 1 | E26: Notes:
A27: 44093 | B27: 1 | E27: =_xlfn.LET(_xlpm.calc,COUNTIFS(All_Time_and_Pay_IDs[Source],"Time Data"),_xlpm.oneK,TEXT(_xlpm.calc,"0,000"),_xlfn.CONCAT("~ There are ",IF(_xlpm.calc>=1000,_xlpm.oneK,_xlpm.calc)," employees in the time data that are not in the pay data.")) -> ~ There are 0 employees in the time data that are not in the pay data.
A28: 44097 | C28: 1 | E28: =_xlfn.LET(_xlpm.calc,COUNTIFS(All_Time_and_Pay_IDs[Source],"Pay Data"),_xlpm.oneK,TEXT(_xlpm.calc,"0,000"),_xlfn.CONCAT("~ There are ",IF(_xlpm.calc>=1000,_xlpm.oneK,_xlpm.calc)," employees in the pay data that are not in the time data.")) -> ~ There are 0 employees in the pay data that are not in the time data.
A29: 44107 | B29: 1 | E29: =_xlfn.LET(_xlpm.calc,COUNTIFS(All_Time_and_Pay_IDs[Source],"Time Data; Pay Data"),_xlpm.oneK,TEXT(_xlpm.calc,"0,000"),_xlfn.CONCAT("~ There are ",IF(_xlpm.calc>=1000,_xlpm.oneK,_xlpm.calc)," employees in both the time and pay data.")) -> ~ There are 0 employees in both the time and pay data.
A30: 44111 | C30: 1 | E30: =_xlfn.LET(_xlpm.time_calc,COUNTIFS(All_Time_and_Pay_IDs[Source],"*time*"),_xlpm.pay_calc,COUNTIFS(All_Time_and_Pay_IDs[Source],"*pay*"),_xlpm.calc,COUNTIFS(All_Time_and_Pay_IDs[Source],"*data*"),_xlpm.time1K,TEXT(_xlpm.time_calc,"0,000"),_xlpm.pay1K,TEXT(_xlpm.pay_calc,"0,000"),_xlpm.calc1K,TEXT(_xlpm.calc,"0,000"),_xlfn.CONCAT("~ There are ",IF(_xlpm.time_calc >= 1000,_xlpm.time1K,_xlpm.time_calc)," unique employees in time data, ",IF(_xlpm.pay_calc >= 1000,_xlpm.pay1K,_xlpm.pay_calc)," in the pay data and ",IF(_xlpm.calc >= 1000,_xlpm.calc1K,_xlpm.calc)," in combined time and pay data.")) -> ~ There are 0 unique employees in time data, 0 in the pay data and 0 in combined time and pay data.
A31: 44121 | B31: 1
A32: 44125 | C32: 1
A33: 44135 | B33: 1
A34: 44139 | C34: 1
A35: 44149 | B35: 1
A36: 44153 | C36: 1
A37: 44163 | B37: 1
A38: 44167 | C38: 1
A39: 44177 | B39: 1
A40: 44181 | C40: 1
...

Sheet Employee Pay Period Comparison
A1: ID | B1: Time_Periods | C1: Time_First_Date | D1: Time_Last_Date | E1: Time_Records | F1: Pay_Periods | G1: Pay_First_Date | H1: Pay_Last_Date | I1: Pay_Records | J1: Matching_Periods | K1: Time_Only_Periods | L1: Pay_Only_Periods | M1: Total_Unique_Periods | N1: Match_Rate | O1: Time_Coverage | P1: Pay_Coverage | Q1: Data_Status

Sheet Analysis
A1: Metric Group | B1: Metric Label | C1: Waiver Scenario | D1: Extrapolated | E1: All Data | F1: 2020 | G1: 2021 | H1: 2022 | I1: 2023 | J1: 2024 | K1: 2025 | L1: 2026 | M1: Barraza-Benitez, Hector

Sheet PAGA Analysis
D1: ='Class Analysis'!$D$1 -> Extrap | E1: ='Class Analysis'!$E$1 -> e | F1: ='Class Analysis'!$M$1 -> #NAME?
D2: ='Class Analysis'!$D$3 -> Extrap thru 3/2/2026 | E2: All Data | F2: =F1 -> #NAME? | G2: Notes | H2: Ref_1 | I2: Ref_2
B3: General Statistics | C3: Start date | D3: =ref!$B$6 -> 44497 | E3: {=MAX($D3,_xlfn.LET(_xlpm.calc,_xlfn.MINIFS(Date,Key_Gps,"*"&E$1&"*"),IF(ISNUMBER(E$2),IF(OR(DATE(E$2,12,31) < MIN(Date),DATE(E$2,1,1)>MAX(Date)), "-", MAX(DATE(E$2,1,1),_xlpm.calc)),_xlpm.calc)))} -> #NAME? | F3: {=MAX($D3,_xlfn.LET(_xlpm.calc,_xlfn.MINIFS(Date,Key_Gps,"*"&F$1&"*"),IF(ISNUMBER(F$2),IF(OR(DATE(F$2,12,31) < MIN(Date),DATE(F$2,1,1)>MAX(Date)), "-", MAX(DATE(F$2,1,1),_xlpm.calc)),_xlpm.calc)))} -> #NAME? | G3: =IF('Class Analysis'!N4="","",'Class Analysis'!N4) -> Complaint filed 01/01/2023.
C4: End date | D4: =ref!$B$3 -> 46083 | E4: {=_xlfn.LET(_xlpm.calc,_xlfn.MAXIFS(Period_End,Key_Gps,"*"&E$1&"*"),IF(ISNUMBER(E$2),IF(DATE(E$2,12,31) < MIN(Period_End), "-", MIN(DATE(E$2,12,31),_xlpm.calc)),_xlpm.calc))} -> #NAME? | F4: {=_xlfn.LET(_xlpm.calc,_xlfn.MAXIFS(Period_End,Key_Gps,"*"&F$1&"*"),IF(ISNUMBER(F$2),IF(DATE(F$2,12,31) < MIN(Period_End), "-", MIN(DATE(F$2,12,31),_xlpm.calc)),_xlpm.calc))} -> #NAME? | G4: =IF('Class Analysis'!N5="","",'Class Analysis'!N5)
C5: Employees | D5: =E5*ref!$B$4 -> 0 | E5: {=IFERROR(ROWS(_xlfn.UNIQUE(_xlfn._xlws.FILTER(ID,(Date >= E$3) * (Date <= E$4) * (IFERROR(SEARCH(E$1, Key_Gps),0)>0)))),0)} -> 0 | F5: {=IFERROR(ROWS(_xlfn.UNIQUE(_xlfn._xlws.FILTER(ID,(Date >= F$3) * (Date <= F$4) * (IFERROR(SEARCH(F$1, Key_Gps),0)>0)))),0)} -> 0 | G5: =IF('Class Analysis'!N6="","",'Class Analysis'!N6) -> Values provided by defense counsel.
C6: Former employees | D6: =ROUND(E6/E5*D5,0) -> #NAME? | E6: {=_xlfn.LET(_xlpm.active,ROWS(_xlfn.UNIQUE(_xlfn._xlws.FILTER(Pay_ID, (Pay_Period_End > MAX(Pay_Period_End) - $H$6)))),E5-_xlpm.active)} -> #NAME? | F6: =F5 -> 0 | H6: 30
C7: Active employees | D7: =IFERROR(D5-D6,"-") -> - | E7: =IFERROR(E5-E6,"-") -> - | F7: =IFERROR(F5-F6,"-") -> 0 | G7: Assumes active if worked in final 30 days of pay data.
C8: Pay periods | D8: =ROUND((E8*ref!$B$4)/ref!$B$9,0) -> #NAME? | E8: {=IFERROR(ROWS(_xlfn.UNIQUE(_xlfn._xlws.FILTER(ID_Period_End,(Period_End >= E$3) * (Period_End <= E$4) * (IFERROR(SEARCH(E$1, Key_Gps),0)>0)))),0)} -> 0 | F8: {=IFERROR(ROWS(_xlfn.UNIQUE(_xlfn._xlws.FILTER(ID_Period_End,(Period_End >= F$3) * (Period_End <= F$4) * (IFERROR(SEARCH(F$1, Key_Gps),0)>0)))),0)} -> 0 | G8: ='Class Analysis'!N7 -> ERROR
B10: Meals (shifts >5 hrs) | C10: Employees with at least one shift >5 hrs with a short, late or missing meal | D10: =ROUND(E11*D$5,0) -> #VALUE! | E10: {=IFERROR(ROWS(_xlfn.UNIQUE(_xlfn._xlws.FILTER(ID,(Date >= E$3) * (Date <= E$4) * (IFERROR(SEARCH(E$1, Key_Gps),0)>0) * (mpv_per_pp > 0)))),0)} -> 0 | F10: {=IFERROR(ROWS(_xlfn.UNIQUE(_xlfn._xlws.FILTER(ID,(Date >= F$3) * (Date <= F$4) * (IFERROR(SEARCH(F$1, Key_Gps),0)>0) * (mpv_per_pp > 0)))),0)} -> 0 | G10: Assumes no waivers.
C11: % of all employees | D11: =IFERROR(ROUND(D10/D$5,3),"-") -> - | E11: =IFERROR(ROUND(E10/E$5,3),"-") -> - | F11: =IFERROR(ROUND(F10/F$5,3),"-") -> - | H11: Calculated Violation Rate Applied
C12: Pay periods with at least one shift >5 hrs with a short, late or missing meal | D12: =ROUND($E13*D$8,0) -> #VALUE! | E12: {=IF($H11="Calculated Violation Rate Applied",IFERROR(ROWS(_xlfn.UNIQUE(_xlfn._xlws.FILTER(ID_Period_End,(Period_End >= E$3) * (Period_End <= E$4) * (IFERROR(SEARCH(E$1, Key_Gps),0)>0) * (mpv_per_pp > 0)))),0),ROUND(E$8*$H12,0))} -> 0 | F12: {=IF($H11="Calculated Violation Rate Applied",IFERROR(ROWS(_xlfn.UNIQUE(_xlfn._xlws.FILTER(ID_Period_End,(Period_End >= F$3) * (Period_End <= F$4) * (IFERROR(SEARCH(F$1, Key_Gps),0)>0) * (mpv_per_pp > 0)))),0),ROUND(F$8*$H12,0))} -> 0 | H12: =I12 -> #DIV/0! | I12: {=ROUND(IFERROR(ROWS(_xlfn.UNIQUE(_xlfn._xlws.FILTER(ID_Period_End,(Period_End >= E$3) * (Period_End <= E$4) * (IFERROR(SEARCH(E$1, Key_Gps),0)>0) * (mpv_per_pp > 0)))),0) / IFERROR(ROWS(_xlfn.UNIQUE(_xlfn._xlws.FILTER(ID_Period_End,(Period_End >= E$3) * (Period_End <= E$4) * (IFERROR(SEARCH(E$1, Key_Gps),0)>0)))),0),3)} -> #DIV/0!
C13: % of total pay periods | D13: =IFERROR(ROUND(D12/D$8,3),"-") -> - | E13: =IFERROR(ROUND(E12/E$8,3),"-") -> - | F13: =IFERROR(ROUND(F12/F$8,3),"-") -> - | G13: =IF(INT(H12)=H12,_xlfn.CONCAT("Violation rate: ",TEXT(H12,"0%")),_xlfn.CONCAT("Violation rate: ",TEXT(H12,"0.0%"))) -> #DIV/0!
C14: Meal period PAGA damages (shifts >5 hrs) | D14: =IF(D12=0,0,IF(D12=1,$H14,($H14*D$5)+((D12-D$5)*$I14))) -> #VALUE! | E14: =IF(E12=0,0,IF(E12=1,$H14,($H14*E$5)+((E12-E$5)*$I14))) -> 0 | F14: =IF(F12=0,0,IF(F12=1,$H14,($H14*F$5)+((F12-F$5)*$I14))) -> 0 | G14: =IF(H14=I14,_xlfn.CONCAT("Assumes ",TEXT(H14,"$0")," for initial and subsequent violations (PPs)."),_xlfn.CONCAT("Assumes ",TEXT(H14,"$0")," for initial violation (PP) and ",TEXT(I14,"$0")," for subsequent violations (PPs).")) -> Assumes $100 for initial and subsequent violations (PPs). | H14: 100 | I14: 100
B16: Meals (shifts >6 hrs) | C16: Employees with at least one shift >6 hrs with a short, late or missing meal | D16: =ROUND(E17*D$5,0) -> #VALUE! | E16: {=IFERROR(ROWS(_xlfn.UNIQUE(_xlfn._xlws.FILTER(ID,(Date >= E$3) * (Date <= E$4) * (IFERROR(SEARCH(E$1, Key_Gps),0)>0) * (mpv_per_pp_w > 0)))),0)} -> 0 | F16: {=IFERROR(ROWS(_xlfn.UNIQUE(_xlfn._xlws.FILTER(ID,(Date >= F$3) * (Date <= F$4) * (IFERROR(SEARCH(F$1, Key_Gps),0)>0) * (mpv_per_pp_w > 0)))),0)} -> 0 | G16: Assumes waivers.
C17: % of all employees | D17: =IFERROR(ROUND(D16/D$5,3),"-") -> - | E17: =IFERROR(ROUND(E16/E$5,3),"-") -> - | F17: =IFERROR(ROUND(F16/F$5,3),"-") -> - | H17: Calculated Violation Rate Applied
C18: Pay periods with at least one shift >6 hrs with a short, late or missing meal | D18: =ROUND($E19*D$8,0) -> #VALUE! | E18: {=IF($H17="Calculated Violation Rate Applied",IFERROR(ROWS(_xlfn.UNIQUE(_xlfn._xlws.FILTER(ID_Period_End,(Period_End >= E$3) * (Period_End <= E$4) * (IFERROR(SEARCH(E$1, Key_Gps),0)>0) * (mpv_per_pp_w > 0)))),0),ROUND(E$8*$H18,0))} -> 0 | F18: {=IF($H17="Calculated Violation Rate Applied",IFERROR(ROWS(_xlfn.UNIQUE(_xlfn._xlws.FILTER(ID_Period_End,(Period_End >= F$3) * (Period_End <= F$4) * (IFERROR(SEARCH(F$1, Key_Gps),0)>0) * (mpv_per_pp_w > 0)))),0),ROUND(F$8*$H18,0))} -> 0 | H18: =I18 -> #DIV/0! | I18: {=ROUND(IFERROR(ROWS(_xlfn.UNIQUE(_xlfn._xlws.FILTER(ID_Period_End,(Period_End >= E$3) * (Period_End <= E$4) * (IFERROR(SEARCH(E$1, Key_Gps),0)>0) * (mpv_per_pp_w > 0)))),0) / IFERROR(ROWS(_xlfn.UNIQUE(_xlfn._xlws.FILTER(ID_Period_End,(Period_End >= E$3) * (Period_End <= E$4) * (IFERROR(SEARCH(E$1, Key_Gps),0)>0)))),0),3)} -> #DIV/0!
C19: % of total pay periods | D19: =IFERROR(ROUND(D18/D$8,3),"-") -> - | E19: =IFERROR(ROUND(E18/E$8,3),"-") -> - | F19: =IFERROR(ROUND(F18/F$8,3),"-") -> - | G19: =IF(INT(H18)=H18,_xlfn.CONCAT("Violation rate: ",TEXT(H18,"0%")),_xlfn.CONCAT("Violation rate: ",TEXT(H18,"0.0%"))) -> #DIV/0!
C20: Meal period PAGA damages (shifts >6 hrs) | D20: =IF(D18=0,0,IF(D18=1,$H20,($H20*D$5)+((D18-D$5)*$I20))) -> #VALUE! | E20: =IF(E18=0,0,IF(E18=1,$H20,($H20*E$5)+((E18-E$5)*$I20))) -> 0 | F20: =IF(F18=0,0,IF(F18=1,$H20,($H20*F$5)+((F18-F$5)*$I20))) -> 0 | G20: =IF(H20=I20,_xlfn.CONCAT("Assumes ",TEXT(H20,"$0")," for initial and subsequent violations (PPs)."),_xlfn.CONCAT("Assumes ",TEXT(H20,"$0")," for initial violation (PP) and ",TEXT(I20,"$0")," for subsequent violations (PPs).")) -> Assumes $100 for initial and subsequent violations (PPs). | H20: 100 | I20: 100
B22: Meals, Less Premiums (shifts >5 hrs) | C22: Employees with at least one shift >5 hrs with a short, late or missing meal, less meal premiums | D22: =ROUND(E23*D$5,0) -> #VALUE! | E22: {=IFERROR(ROWS(_xlfn.UNIQUE(_xlfn._xlws.FILTER(ID,(Date >= E$3) * (Date <= E$4) * (IFERROR(SEARCH(E$1, Key_Gps),0)>0) * (mpv_per_pp_less_prems > 0)))),0)} -> 0 | F22: {=IFERROR(ROWS(_xlfn.UNIQUE(_xlfn._xlws.FILTER(ID,(Date >= F$3) * (Date <= F$4) * (IFERROR(SEARCH(F$1, Key_Gps),0)>0) * (mpv_per_pp_less_prems > 0)))),0)} -> 0 | G22: Assumes no waivers. Credits meal premiums already paid.
C23: % of all employees | D23: =IFERROR(ROUND(D22/D$5,3),"-") -> - | E23: =IFERROR(ROUND(E22/E$5,3),"-") -> - | F23: =IFERROR(ROUND(F22/F$5,3),"-") -> - | H23: Calculated Violation Rate Applied
C24: Pay periods with at least one shift >5 hrs with a short, late or missing meal, less meal premiums | D24: =ROUND($E25*D$8,0) -> #VALUE! | E24: {=IF($H23="Calculated Violation Rate Applied",IFERROR(ROWS(_xlfn.UNIQUE(_xlfn._xlws.FILTER(ID_Period_End,(Period_End >= E$3) * (Period_End <= E$4) * (IFERROR(SEARCH(E$1, Key_Gps),0)>0) * (mpv_per_pp_less_prems > 0)))),0),ROUND(E$8*$H24,0))} -> 0 | F24: {=IF($H23="Calculated Violation Rate Applied",IFERROR(ROWS(_xlfn.UNIQUE(_xlfn._xlws.FILTER(ID_Period_End,(Period_End >= F$3) * (Period_End <= F$4) * (IFERROR(SEARCH(F$1, Key_Gps),0)>0) * (mpv_per_pp_less_prems > 0)))),0),ROUND(F$8*$H24,0))} -> 0 | H24: =I24 -> #DIV/0! | I24: {=ROUND(IFERROR(ROWS(_xlfn.UNIQUE(_xlfn._xlws.FILTER(ID_Period_End,(Period_End >= E$3) * (Period_End <= E$4) * (IFERROR(SEARCH(E$1, Key_Gps),0)>0) * (mpv_per_pp_less_prems > 0)))),0) / IFERROR(ROWS(_xlfn.UNIQUE(_xlfn._xlws.FILTER(ID_Period_End,(Period_End >= E$3) * (Period_End <= E$4) * (IFERROR(SEARCH(E$1, Key_Gps),0)>0)))),0),3)} -> #DIV/0!
C25: % of total pay periods | D25: =IFERROR(ROUND(D24/D$8,3),"-") -> - | E25: =IFERROR(ROUND(E24/E$8,3),"-") -> - | F25: =IFERROR(ROUND(F24/F$8,3),"-") -> - | G25: =IF(INT(H24)=H24,_xlfn.CONCAT("Violation rate: ",TEXT(H24,"0%")),_xlfn.CONCAT("Violation rate: ",TEXT(H24,"0.0%"))) -> #DIV/0!
C26: Meal period PAGA damages (shifts >5 hrs) | D26: =IF(D24=0,0,IF(D24=1,$H26,($H26*D$5)+((D24-D$5)*$I26))) -> #VALUE! | E26: =IF(E24=0,0,IF(E24=1,$H26,($H26*E$5)+((E24-E$5)*$I26))) -> 0 | F26: =IF(F24=0,0,IF(F24=1,$H26,($H26*F$5)+((F24-F$5)*$I26))) -> 0 | G26: =IF(H26=I26,_xlfn.CONCAT("Assumes ",TEXT(H26,"$0")," for initial and subsequent violations (PPs)."),_xlfn.CONCAT("Assumes ",TEXT(H26,"$0")," for initial violation (PP) and ",TEXT(I26,"$0")," for subsequent violations (PPs).")) -> Assumes $100 for initial and subsequent violations (PPs). | H26: 100 | I26: 100
B28: Meals, Less Premiums (shifts >6 hrs) | C28: Employees with at least one shift >6 hrs with a short, late or missing meal, less meal premiums | D28: =ROUND(E29*D$5,0) -> #VALUE! | E28: {=IFERROR(ROWS(_xlfn.UNIQUE(_xlfn._xlws.FILTER(ID,(Date >= E$3) * (Date <= E$4) * (IFERROR(SEARCH(E$1, Key_Gps),0)>0) * (mpv_per_pp_less_prems_w > 0)))),0)} -> 0 | F28: {=IFERROR(ROWS(_xlfn.UNIQUE(_xlfn._xlws.FILTER(ID,(Date >= F$3) * (Date <= F$4) * (IFERROR(SEARCH(F$1, Key_Gps),0)>0) * (mpv_per_pp_less_prems_w > 0)))),0)} -> 0 | G28: Assumes waivers. Credits meal premiums already paid.
C29: % of all employees | D29: =IFERROR(ROUND(D28/D$5,3),"-") -> - | E29: =IFERROR(ROUND(E28/E$5,3),"-") -> - | F29: =IFERROR(ROUND(F28/F$5,3),"-") -> - | H29: Calculated Violation Rate Applied
C30: Pay periods with at least one shift >6 hrs with a short, late or missing meal, less meal premiums | D30: =ROUND($E31*D$8,0) -> #VALUE! | E30: {=IF($H29="Calculated Violation Rate Applied",IFERROR(ROWS(_xlfn.UNIQUE(_xlfn._xlws.FILTER(ID_Period_End,(Period_End >= E$3) * (Period_End <= E$4) * (IFERROR(SEARCH(E$1, Key_Gps),0)>0) * (mpv_per_pp_less_prems_w > 0)))),0),ROUND(E$8*$H30,0))} -> 0 | F30: {=IF($H29="Calculated Violation Rate Applied",IFERROR(ROWS(_xlfn.UNIQUE(_xlfn._xlws.FILTER(ID_Period_End,(Period_End >= F$3) * (Period_End <= F$4) * (IFERROR(SEARCH(F$1, Key_Gps),0)>0) * (mpv_per_pp_less_prems_w > 0)))),0),ROUND(F$8*$H30,0))} -> 0 | H30: =I30 -> #DIV/0! | I30: {=ROUND(IFERROR(ROWS(_xlfn.UNIQUE(_xlfn._xlws.FILTER(ID_Period_End,(Period_End >= E$3) * (Period_End <= E$4) * (IFERROR(SEARCH(E$1, Key_Gps),0)>0) * (mpv_per_pp_less_prems_w > 0)))),0) / IFERROR(ROWS(_xlfn.UNIQUE(_xlfn._xlws.FILTER(ID_Period_End,(Period_End >= E$3) * (Period_End <= E$4) * (IFERROR(SEARCH(E$1, Key_Gps),0)>0)))),0),3)} -> #DIV/0!
C31: % of total pay periods | D31: =IFERROR(ROUND(D30/D$8,3),"-") -> - | E31: =IFERROR(ROUND(E30/E$8,3),"-") -> - | F31: =IFERROR(ROUND(F30/F$8,3),"-") -> - | G31: =IF(INT(H30)=H30,_xlfn.CONCAT("Violation rate: ",TEXT(H30,"0%")),_xlfn.CONCAT("Violation rate: ",TEXT(H30,"0.0%"))) -> #DIV/0!
C32: Meal period PAGA damages (shifts >6 hrs) | D32: =IF(D30=0,0,IF(D30=1,$H32,($H32*D$5)+((D30-D$5)*$I32))) -> #VALUE! | E32: =IF(E30=0,0,IF(E30=1,$H32,($H32*E$5)+((E30-E$5)*$I32))) -> 0 | F32: =IF(F30=0,0,IF(F30=1,$H32,($H32*F$5)+((F30-F$5)*$I32))) -> 0 | G32: =IF(H32=I32,_xlfn.CONCAT("Assumes ",TEXT(H32,"$0")," for initial and subsequent violations (PPs)."),_xlfn.CONCAT("Assumes ",TEXT(H32,"$0")," for initial violation (PP) and ",TEXT(I32,"$0")," for subsequent violations (PPs).")) -> Assumes $100 for initial and subsequent violations (PPs). | H32: 100 | I32: 100
B34: Rest Periods | C34: Employees with at least one rest period eligible shift | D34: =ROUND(E35*D$5,0) -> #VALUE! | E34: {=IFERROR(ROWS(_xlfn.UNIQUE(_xlfn._xlws.FILTER(ID,(Date >= E$3) * (Date <= E$4) * (IFERROR(SEARCH(E$1, Key_Gps),0)>0) * (rpv_shift = 1)))),0)} -> 0 | F34: {=IFERROR(ROWS(_xlfn.UNIQUE(_xlfn._xlws.FILTER(ID,(Date >= F$3) * (Date <= F$4) * (IFERROR(SEARCH(F$1, Key_Gps),0)>0) * (rpv_shift = 1)))),0)} -> 0 | G34: Rest period eligible = shift >3.5 hrs.
C35: % of all employees | D35: =IFERROR(ROUND(D34/D$5,3),"-") -> - | E35: =IFERROR(ROUND(E34/E$5,3),"-") -> - | F35: =IFERROR(ROUND(F34/F$5,3),"-") -> - | H35: Calculated Violation Rate Applied
C36: Pay periods with at least one rest period eligible shift | D36: =ROUND($E37*D$8,0) -> #VALUE! | E36: {=IF($H35="Calculated Violation Rate Applied",IFERROR(ROWS(_xlfn.UNIQUE(_xlfn._xlws.FILTER(ID_Period_End,(Period_End >= E$3) * (Period_End <= E$4) * (IFERROR(SEARCH(E$1, Key_Gps),0)>0) * (rpv_shift > 0)))),0),ROUND(E$8*$H36,0))} -> 0 | F36: {=IF($H35="Calculated Violation Rate Applied",IFERROR(ROWS(_xlfn.UNIQUE(_xlfn._xlws.FILTER(ID_Period_End,(Period_End >= F$3) * (Period_End <= F$4) * (IFERROR(SEARCH(F$1, Key_Gps),0)>0) * (rpv_shift > 0)))),0),ROUND(F$8*$H36,0))} -> 0 | H36: =I36 -> #DIV/0! | I36: {=ROUND(IFERROR(ROWS(_xlfn.UNIQUE(_xlfn._xlws.FILTER(ID_Period_End,(Period_End >= E$3) * (Period_End <= E$4) * (IFERROR(SEARCH(E$1, Key_Gps),0)>0) * (rpv_shift = 1)))),0) / IFERROR(ROWS(_xlfn.UNIQUE(_xlfn._xlws.FILTER(ID_Period_End,(Period_End >= E$3) * (Period_End <= E$4) * (IFERROR(SEARCH(E$1, Key_Gps),0)>0)))),0),3)} -> #DIV/0!
C37: % of total pay periods | D37: =IFERROR(ROUND(D36/D$8,3),"-") -> - | E37: =IFERROR(ROUND(E36/E$8,3),"-") -> - | F37: =IFERROR(ROUND(F36/F$8,3),"-") -> - | G37: =IF(INT(H36)=H36,_xlfn.CONCAT("Violation rate: ",TEXT(H36,"0%")),_xlfn.CONCAT("Violation rate: ",TEXT(H36,"0.0%"))) -> #DIV/0!
C38: Rest period PAGA damages | D38: =IF(D36=0,0,IF(D36=1,$H38,($H38*D$5)+((D36-D$5)*$I38))) -> #VALUE! | E38: =IF(E36=0,0,IF(E36=1,$H38,($H38*E$5)+((E36-E$5)*$I38))) -> 0 | F38: =IF(F36=0,0,IF(F36=1,$H38,($H38*F$5)+((F36-F$5)*$I38))) -> 0 | G38: =IF(H38=I38,_xlfn.CONCAT("Assumes ",TEXT(H38,"$0")," for initial and subsequent violations (PPs)."),_xlfn.CONCAT("Assumes ",TEXT(H38,"$0")," for initial violation (PP) and ",TEXT(I38,"$0")," for subsequent violations (PPs).")) -> Assumes $100 for initial and subsequent violations (PPs). | H38: 100 | I38: 100
B40: 226.3 | C40: Pay periods | D40: =ROUND($E41*D$8,0) -> #VALUE! | E40: =MAX(E$36,E$18,E$12) -> 0 | F40: =MAX(F$36,F$18,F$12) -> 0
C41: % of total pay periods | D41: =IFERROR(ROUND(D40/D$8,3),"-") -> - | E41: =IFERROR(ROUND(E40/E$8,3),"-") -> - | F41: =IFERROR(ROUND(F40/F$8,3),"-") -> -
C42: Failure to provide wage deduction statement or fails to keep the records required | D42: =IF(D40=0,0,IF(D40=1,$H42,($H42*D$5)+((D40-D$5)*$I42))) -> #VALUE! | E42: =IF(E40=0,0,IF(E40=1,$H42,($H42*E$5)+((E40-E$5)*$I42))) -> 0 | F42: =IF(F40=0,0,IF(F40=1,$H42,($H42*F$5)+((F40-F$5)*$I42))) -> 0 | G42: =IF(H42=I42,_xlfn.CONCAT("Assumes ",TEXT(H42,"$0")," for initial and subsequent violations (PPs)."),_xlfn.CONCAT("Assumes ",TEXT(H42,"$0")," for initial violation (PP) and ",TEXT(I42,"$0")," for subsequent violations (PPs).")) -> Assumes $250 for initial and subsequent violations (PPs). | H42: 250 | I42: 250
B44: 558 | C44: Pay periods | D44: =ROUND($E45*D$8,0) -> #VALUE! | E44: =MAX(E$18,E$12) -> 0 | F44: =MAX(F$18,F$12) -> 0
C45: % of total pay periods | D45: =IFERROR(ROUND(D44/D$8,3),"-") -> - | E45: =IFERROR(ROUND(E44/E$8,3),"-") -> - | F45: =IFERROR(ROUND(F44/F$8,3),"-") -> -
C46: Failure to pay overtime | D46: =IF(D44=0,0,IF(D44=1,$H46,($H46*D$5)+((D44-D$5)*$I46))) -> #VALUE! | E46: =IF(E44=0,0,IF(E44=1,$H46,($H46*E$5)+((E44-E$5)*$I46))) -> 0 | F46: =IF(F44=0,0,IF(F44=1,$H46,($H46*F$5)+((F44-F$5)*$I46))) -> 0 | G46: =IF(H46=I46,_xlfn.CONCAT("Assumes ",TEXT(H46,"$0")," for initial and subsequent violations (PPs)."),_xlfn.CONCAT("Assumes ",TEXT(H46,"$0")," for initial violation (PP) and ",TEXT(I46,"$0")," for subsequent violations (PPs).")) -> Assumes $50 for initial and subsequent violations (PPs). | H46: 50 | I46: 50
B48: 1174.5 | C48: Employees | D48: =D$5 -> 0 | E48: =E$5 -> 0 | F48: =F$5 -> 0
...

Sheet Class Analysis
A1: 1 | D1: Extrap | E1: e | F1: =$E$1 -> e | G1: =$E$1 -> e | H1: =$E$1 -> e | I1: =$E$1 -> e | J1: =$E$1 -> e | K1: =$E$1 -> e | L1: =$E$1 -> e | M1: {=INDEX(Key_Gps, MATCH(TRUE, Key_Gps<>"Everyone Else", 0))} -> #NAME? | N1: Notes | O1: Ref_1 | P1: Ref_2 | Q1: Extrap %s | R1: Check | S1: Ref_3 | T1: =D1 -> Extrap | U1: =E1 -> e | V1: =F1 -> e | W1: =G1 -> e | X1: =H1 -> e | Y1: =I1 -> e | Z1: =J1 -> e | AA1: =K1 -> e | ... AC1: =M1 -> #NAME?
D2: Extrapolation | E2: Data Sample | M2: Named Plaintiff | N2: Notes
A3: 1 | D3: =_xlfn.CONCAT("Extrap thru ",TEXT(D5,"m/d/yyyy")) -> Extrap thru 3/2/2026 | E3: All Data | F3: 2020 | G3: 2021 | H3: 2022 | I3: 2023 | J3: 2024 | K3: 2025 | L3: 2026 | M3: =M1 -> #NAME? | O3: =O1 -> Ref_1 | P3: =P1 -> Ref_2 | Q3: Extrap %s | R3: Check | S3: Ref_3 | T3: =D3 -> Extrap thru 3/2/2026 | U3: =E3 -> All Data | V3: =F3 -> 2020 | W3: =G3 -> 2021 | X3: =H3 -> 2022 | Y3: =I3 -> 2023 | Z3: =J3 -> 2024 | AA3: =K3 -> 2025 | ... AC3: =M3 -> #NAME?
B4: Time Data Statistics | C4: Start date | D4: =ref!$B$7 -> 43466 | E4: {=_xlfn.LET(_xlpm.calc,_xlfn.MINIFS(Date,Key_Gps,"*"&E$1&"*"),IF(ISNUMBER(E$3),IF(OR(DATE(E$3,12,31) < MIN(Date),DATE(E$3,1,1)>MAX(Date)), "-", MAX(DATE(E$3,1,1),_xlpm.calc)),_xlpm.calc))} -> #NAME? | F4: {=_xlfn.LET(_xlpm.calc,_xlfn.MINIFS(Date,Key_Gps,"*"&F$1&"*"),IF(ISNUMBER(F$3),IF(OR(DATE(F$3,12,31) < MIN(Date),DATE(F$3,1,1)>MAX(Date)), "-", MAX(DATE(F$3,1,1),_xlpm.calc)),_xlpm.calc))} -> #NAME? | G4: {=_xlfn.LET(_xlpm.calc,_xlfn.MINIFS(Date,Key_Gps,"*"&G$1&"*"),IF(ISNUMBER(G$3),IF(OR(DATE(G$3,12,31) < MIN(Date),DATE(G$3,1,1)>MAX(Date)), "-", MAX(DATE(G$3,1,1),_xlpm.calc)),_xlpm.calc))} -> #NAME? | H4: {=_xlfn.LET(_xlpm.calc,_xlfn.MINIFS(Date,Key_Gps,"*"&H$1&"*"),IF(ISNUMBER(H$3),IF(OR(DATE(H$3,12,31) < MIN(Date),DATE(H$3,1,1)>MAX(Date)), "-", MAX(DATE(H$3,1,1),_xlpm.calc)),_xlpm.calc))} -> #NAME? | I4: {=_xlfn.LET(_xlpm.calc,_xlfn.MINIFS(Date,Key_Gps,"*"&I$1&"*"),IF(ISNUMBER(I$3),IF(OR(DATE(I$3,12,31) < MIN(Date),DATE(I$3,1,1)>MAX(Date)), "-", MAX(DATE(I$3,1,1),_xlpm.calc)),_xlpm.calc))} -> #NAME? | J4: {=_xlfn.LET(_xlpm.calc,_xlfn.MINIFS(Date,Key_Gps,"*"&J$1&"*"),IF(ISNUMBER(J$3),IF(OR(DATE(J$3,12,31) < MIN(Date),DATE(J$3,1,1)>MAX(Date)), "-", MAX(DATE(J$3,1,1),_xlpm.calc)),_xlpm.calc))} -> #NAME? | K4: {=_xlfn.LET(_xlpm.calc,_xlfn.MINIFS(Date,Key_Gps,"*"&K$1&"*"),IF(ISNUMBER(K$3),IF(OR(DATE(K$3,12,31) < MIN(Date),DATE(K$3,1,1)>MAX(Date)), "-", MAX(DATE(K$3,1,1),_xlpm.calc)),_xlpm.calc))} -> #NAME? | L4: {=_xlfn.LET(_xlpm.calc,_xlfn.MINIFS(Date,Key_Gps,"*"&L$1&"*"),IF(ISNUMBER(L$3),IF(OR(DATE(L$3,12,31) < MIN(Date),DATE(L$3,1,1)>MAX(Date)), "-", MAX(DATE(L$3,1,1),_xlpm.calc)),_xlpm.calc))} -> #NAME? | M4: {=_xlfn.LET(_xlpm.calc,_xlfn.MINIFS(Date,Key_Gps,"*"&M$1&"*"),IF(ISNUMBER(M$3),IF(OR(DATE(M$3,12,31) < MIN(Date),DATE(M$3,1,1)>MAX(Date)), "-", MAX(DATE(M$3,1,1),_xlpm.calc)),_xlpm.calc))} -> #NAME? | N4: ="Complaint filed "&TEXT(ref!$B$1,"mm/dd/yyyy")&"." -> Complaint filed 01/01/2023. | Q4: =IF(IFERROR(SEARCH("(",E4),0)=0,"",VALUE(SUBSTITUTE(RIGHT(E4,LEN(E4)-SEARCH("(",E4)),")",""))) | R4: =IF(U4="","",SUM(V4:AB4)-U4) | S4: =IF($C4="","",IF(OR(IFERROR(SEARCH("min wage",LOWER($C4)),0)>0, IFERROR(SEARCH(" per ",LOWER($C4)),0)>0, IFERROR(SEARCH("penalt",LOWER($C4)),0)>0,IFERROR(SEARCH("total",LOWER($C4)),0)>0,IFERROR(SEARCH("interest",LOWER($C4)),0)>0,IFERROR(SEARCH("date",LOWER($C4)),0)>0,IFERROR(SEARCH("employee",LOWER($C4)),0)>0,IFERROR(SEARCH("average",LOWER($C4)),0)>0,IFERROR(SEARCH("median",LOWER($C4)),0)>0),"",1)) | T4: =IF($S4<>1,"",IF(IFERROR(SEARCH("(",D4),0)=0,D4,VALUE(TRIM(LEFT(D4,SEARCH(" (",D4)))))) | U4: =IF($S4<>1,"",IF(IFERROR(SEARCH("(",E4),0)=0,E4,VALUE(TRIM(LEFT(E4,SEARCH(" (",E4)))))) | V4: =IF($S4<>1,"",IF(IFERROR(SEARCH("(",F4),0)=0,F4,VALUE(TRIM(LEFT(F4,SEARCH(" (",F4)))))) | W4: =IF($S4<>1,"",IF(IFERROR(SEARCH("(",G4),0)=0,G4,VALUE(TRIM(LEFT(G4,SEARCH(" (",G4)))))) | X4: =IF($S4<>1,"",IF(IFERROR(SEARCH("(",H4),0)=0,H4,VALUE(TRIM(LEFT(H4,SEARCH(" (",H4)))))) | Y4: =IF($S4<>1,"",IF(IFERROR(SEARCH("(",I4),0)=0,I4,VALUE(TRIM(LEFT(I4,SEARCH(" (",I4)))))) | Z4: =IF($S4<>1,"",IF(IFERROR(SEARCH("(",J4),0)=0,J4,VALUE(TRIM(LEFT(J4,SEARCH(" (",J4)))))) | AA4: =IF($S4<>1,"",IF(IFERROR(SEARCH("(",K4),0)=0,K4,VALUE(TRIM(LEFT(K4,SEARCH(" (",K4)))))) | ... AC4: =IF($S4<>1,"",IF(IFERROR(SEARCH("(",M4),0)=0,M4,VALUE(TRIM(LEFT(M4,SEARCH(" (",M4))))))
C5: End date | D5: =ref!$B$3 -> 46083 | E5: {=_xlfn.LET(_xlpm.calc,_xlfn.MAXIFS(Period_End,Key_Gps,"*"&E$1&"*"),IF(ISNUMBER(E$3),IF(OR(DATE(E$3,12,31) < MIN(Date),DATE(E$3,1,1)>MAX(Date)), "-", MIN(DATE(E$3,12,31),_xlpm.calc)),_xlpm.calc))} -> #NAME? | F5: {=_xlfn.LET(_xlpm.calc,_xlfn.MAXIFS(Period_End,Key_Gps,"*"&F$1&"*"),IF(ISNUMBER(F$3),IF(OR(DATE(F$3,12,31) < MIN(Date),DATE(F$3,1,1)>MAX(Date)), "-", MIN(DATE(F$3,12,31),_xlpm.calc)),_xlpm.calc))} -> #NAME? | G5: {=_xlfn.LET(_xlpm.calc,_xlfn.MAXIFS(Period_End,Key_Gps,"*"&G$1&"*"),IF(ISNUMBER(G$3),IF(OR(DATE(G$3,12,31) < MIN(Date),DATE(G$3,1,1)>MAX(Date)), "-", MIN(DATE(G$3,12,31),_xlpm.calc)),_xlpm.calc))} -> #NAME? | H5: {=_xlfn.LET(_xlpm.calc,_xlfn.MAXIFS(Period_End,Key_Gps,"*"&H$1&"*"),IF(ISNUMBER(H$3),IF(OR(DATE(H$3,12,31) < MIN(Date),DATE(H$3,1,1)>MAX(Date)), "-", MIN(DATE(H$3,12,31),_xlpm.calc)),_xlpm.calc))} -> #NAME? | I5: {=_xlfn.LET(_xlpm.calc,_xlfn.MAXIFS(Period_End,Key_Gps,"*"&I$1&"*"),IF(ISNUMBER(I$3),IF(OR(DATE(I$3,12,31) < MIN(Date),DATE(I$3,1,1)>MAX(Date)), "-", MIN(DATE(I$3,12,31),_xlpm.calc)),_xlpm.calc))} -> #NAME? | J5: {=_xlfn.LET(_xlpm.calc,_xlfn.MAXIFS(Period_End,Key_Gps,"*"&J$1&"*"),IF(ISNUMBER(J$3),IF(OR(DATE(J$3,12,31) < MIN(Date),DATE(J$3,1,1)>MAX(Date)), "-", MIN(DATE(J$3,12,31),_xlpm.calc)),_xlpm.calc))} -> #NAME? | K5: {=_xlfn.LET(_xlpm.calc,_xlfn.MAXIFS(Period_End,Key_Gps,"*"&K$1&"*"),IF(ISNUMBER(K$3),IF(OR(DATE(K$3,12,31) < MIN(Date),DATE(K$3,1,1)>MAX(Date)), "-", MIN(DATE(K$3,12,31),_xlpm.calc)),_xlpm.calc))} -> #NAME? | L5: {=_xlfn.LET(_xlpm.calc,_xlfn.MAXIFS(Period_End,Key_Gps,"*"&L$1&"*"),IF(ISNUMBER(L$3),IF(OR(DATE(L$3,12,31) < MIN(Date),DATE(L$3,1,1)>MAX(Date)), "-", MIN(DATE(L$3,12,31),_xlpm.calc)),_xlpm.calc))} -> #NAME? | M5: {=_xlfn.LET(_xlpm.calc,_xlfn.MAXIFS(Period_End,Key_Gps,"*"&M$1&"*"),IF(ISNUMBER(M$3),IF(OR(DATE(M$3,12,31) < MIN(Date),DATE(M$3,1,1)>MAX(Date)), "-", MIN(DATE(M$3,12,31),_xlpm.calc)),_xlpm.calc))} -> #NAME? | N5: =IF(ref!$B$2=1,"",_xlfn.CONCAT("Sample represents ",TEXT(ref!$B$2,"0%")," of class members.")) | Q5: =IF(IFERROR(SEARCH("(",E5),0)=0,"",VALUE(SUBSTITUTE(RIGHT(E5,LEN(E5)-SEARCH("(",E5)),")",""))) | R5: =IF(U5="","",SUM(V5:AB5)-U5) | S5: =IF($C5="","",IF(OR(IFERROR(SEARCH("min wage",LOWER($C5)),0)>0, IFERROR(SEARCH(" per ",LOWER($C5)),0)>0, IFERROR(SEARCH("penalt",LOWER($C5)),0)>0,IFERROR(SEARCH("total",LOWER($C5)),0)>0,IFERROR(SEARCH("interest",LOWER($C5)),0)>0,IFERROR(SEARCH("date",LOWER($C5)),0)>0,IFERROR(SEARCH("employee",LOWER($C5)),0)>0,IFERROR(SEARCH("average",LOWER($C5)),0)>0,IFERROR(SEARCH("median",LOWER($C5)),0)>0),"",1)) | T5: =IF($S5<>1,"",IF(IFERROR(SEARCH("(",D5),0)=0,D5,VALUE(TRIM(LEFT(D5,SEARCH(" (",D5)))))) | U5: =IF($S5<>1,"",IF(IFERROR(SEARCH("(",E5),0)=0,E5,VALUE(TRIM(LEFT(E5,SEARCH(" (",E5)))))) | V5: =IF($S5<>1,"",IF(IFERROR(SEARCH("(",F5),0)=0,F5,VALUE(TRIM(LEFT(F5,SEARCH(" (",F5)))))) | W5: =IF($S5<>1,"",IF(IFERROR(SEARCH("(",G5),0)=0,G5,VALUE(TRIM(LEFT(G5,SEARCH(" (",G5)))))) | X5: =IF($S5<>1,"",IF(IFERROR(SEARCH("(",H5),0)=0,H5,VALUE(TRIM(LEFT(H5,SEARCH(" (",H5)))))) | Y5: =IF($S5<>1,"",IF(IFERROR(SEARCH("(",I5),0)=0,I5,VALUE(TRIM(LEFT(I5,SEARCH(" (",I5)))))) | Z5: =IF($S5<>1,"",IF(IFERROR(SEARCH("(",J5),0)=0,J5,VALUE(TRIM(LEFT(J5,SEARCH(" (",J5)))))) | AA5: =IF($S5<>1,"",IF(IFERROR(SEARCH("(",K5),0)=0,K5,VALUE(TRIM(LEFT(K5,SEARCH(" (",K5)))))) | ... AC5: =IF($S5<>1,"",IF(IFERROR(SEARCH("(",M5),0)=0,M5,VALUE(TRIM(LEFT(M5,SEARCH(" (",M5))))))
C6: Employees | D6: =E6*ref!$B$4 -> 0 | E6: {=IFERROR(ROWS(_xlfn.UNIQUE(_xlfn._xlws.FILTER(ID,(Date >= E$4) * (Date <= E$5) * (IFERROR(SEARCH(E$1, Key_Gps),0)>0)))),0)} -> 0 | F6: {=IFERROR(ROWS(_xlfn.UNIQUE(_xlfn._xlws.FILTER(ID,(Date >= F$4) * (Date <= F$5) * (IFERROR(SEARCH(F$1, Key_Gps),0)>0)))),0)} -> 0 | G6: {=IFERROR(ROWS(_xlfn.UNIQUE(_xlfn._xlws.FILTER(ID,(Date >= G$4) * (Date <= G$5) * (IFERROR(SEARCH(G$1, Key_Gps),0)>0)))),0)} -> 0 | H6: {=IFERROR(ROWS(_xlfn.UNIQUE(_xlfn._xlws.FILTER(ID,(Date >= H$4) * (Date <= H$5) * (IFERROR(SEARCH(H$1, Key_Gps),0)>0)))),0)} -> 0 | I6: {=IFERROR(ROWS(_xlfn.UNIQUE(_xlfn._xlws.FILTER(ID,(Date >= I$4) * (Date <= I$5) * (IFERROR(SEARCH(I$1, Key_Gps),0)>0)))),0)} -> 0 | J6: {=IFERROR(ROWS(_xlfn.UNIQUE(_xlfn._xlws.FILTER(ID,(Date >= J$4) * (Date <= J$5) * (IFERROR(SEARCH(J$1, Key_Gps),0)>0)))),0)} -> 0 | K6: {=IFERROR(ROWS(_xlfn.UNIQUE(_xlfn._xlws.FILTER(ID,(Date >= K$4) * (Date <= K$5) * (IFERROR(SEARCH(K$1, Key_Gps),0)>0)))),0)} -> 0 | L6: {=IFERROR(ROWS(_xlfn.UNIQUE(_xlfn._xlws.FILTER(ID,(Date >= L$4) * (Date <= L$5) * (IFERROR(SEARCH(L$1, Key_Gps),0)>0)))),0)} -> 0 | M6: {=IFERROR(ROWS(_xlfn.UNIQUE(_xlfn._xlws.FILTER(ID,(Date >= M$4) * (Date <= M$5) * (IFERROR(SEARCH(M$1, Key_Gps),0)>0)))),0)} -> 0 | N6: Values provided by defense counsel. | Q6: =IF(IFERROR(SEARCH("(",E6),0)=0,"",VALUE(SUBSTITUTE(RIGHT(E6,LEN(E6)-SEARCH("(",E6)),")",""))) | R6: =IF(U6="","",SUM(V6:AB6)-U6) | S6: =IF($C6="","",IF(OR(IFERROR(SEARCH("min wage",LOWER($C6)),0)>0, IFERROR(SEARCH(" per ",LOWER($C6)),0)>0, IFERROR(SEARCH("penalt",LOWER($C6)),0)>0,IFERROR(SEARCH("total",LOWER($C6)),0)>0,IFERROR(SEARCH("interest",LOWER($C6)),0)>0,IFERROR(SEARCH("date",LOWER($C6)),0)>0,IFERROR(SEARCH("employee",LOWER($C6)),0)>0,IFERROR(SEARCH("average",LOWER($C6)),0)>0,IFERROR(SEARCH("median",LOWER($C6)),0)>0),"",1)) | T6: =IF($S6<>1,"",IF(IFERROR(SEARCH("(",D6),0)=0,D6,VALUE(TRIM(LEFT(D6,SEARCH(" (",D6)))))) | U6: =IF($S6<>1,"",IF(IFERROR(SEARCH("(",E6),0)=0,E6,VALUE(TRIM(LEFT(E6,SEARCH(" (",E6)))))) | V6: =IF($S6<>1,"",IF(IFERROR(SEARCH("(",F6),0)=0,F6,VALUE(TRIM(LEFT(F6,SEARCH(" (",F6)))))) | W6: =IF($S6<>1,"",IF(IFERROR(SEARCH("(",G6),0)=0,G6,VALUE(TRIM(LEFT(G6,SEARCH(" (",G6)))))) | X6: =IF($S6<>1,"",IF(IFERROR(SEARCH("(",H6),0)=0,H6,VALUE(TRIM(LEFT(H6,SEARCH(" (",H6)))))) | Y6: =IF($S6<>1,"",IF(IFERROR(SEARCH("(",I6),0)=0,I6,VALUE(TRIM(LEFT(I6,SEARCH(" (",I6)))))) | Z6: =IF($S6<>1,"",IF(IFERROR(SEARCH("(",J6),0)=0,J6,VALUE(TRIM(LEFT(J6,SEARCH(" (",J6)))))) | AA6: =IF($S6<>1,"",IF(IFERROR(SEARCH("(",K6),0)=0,K6,VALUE(TRIM(LEFT(K6,SEARCH(" (",K6)))))) | ... AC6: =IF($S6<>1,"",IF(IFERROR(SEARCH("(",M6),0)=0,M6,VALUE(TRIM(LEFT(M6,SEARCH(" (",M6))))))
C7: Pay periods | D7: =ROUND((E7*ref!$B$4)/ref!$B$5,0) -> #NAME? | E7: {=IFERROR(ROWS(_xlfn.UNIQUE(_xlfn._xlws.FILTER(ID_Period_End,(Period_End >= E$4) * (Period_End <= E$5) * (IFERROR(SEARCH(E$1, Key_Gps),0)>0)))),0)} -> 0 | F7: {=IFERROR(ROWS(_xlfn.UNIQUE(_xlfn._xlws.FILTER(ID_Period_End,(Period_End >= F$4) * (Period_End <= F$5) * (IFERROR(SEARCH(F$1, Key_Gps),0)>0)))),0)} -> 0 | G7: {=IFERROR(ROWS(_xlfn.UNIQUE(_xlfn._xlws.FILTER(ID_Period_End,(Period_End >= G$4) * (Period_End <= G$5) * (IFERROR(SEARCH(G$1, Key_Gps),0)>0)))),0)} -> 0 | H7: {=IFERROR(ROWS(_xlfn.UNIQUE(_xlfn._xlws.FILTER(ID_Period_End,(Period_End >= H$4) * (Period_End <= H$5) * (IFERROR(SEARCH(H$1, Key_Gps),0)>0)))),0)} -> 0 | I7: {=IFERROR(ROWS(_xlfn.UNIQUE(_xlfn._xlws.FILTER(ID_Period_End,(Period_End >= I$4) * (Period_End <= I$5) * (IFERROR(SEARCH(I$1, Key_Gps),0)>0)))),0)} -> 0 | J7: {=IFERROR(ROWS(_xlfn.UNIQUE(_xlfn._xlws.FILTER(ID_Period_End,(Period_End >= J$4) * (Period_End <= J$5) * (IFERROR(SEARCH(J$1, Key_Gps),0)>0)))),0)} -> 0 | K7: {=IFERROR(ROWS(_xlfn.UNIQUE(_xlfn._xlws.FILTER(ID_Period_End,(Period_End >= K$4) * (Period_End <= K$5) * (IFERROR(SEARCH(K$1, Key_Gps),0)>0)))),0)} -> 0 | L7: {=IFERROR(ROWS(_xlfn.UNIQUE(_xlfn._xlws.FILTER(ID_Period_End,(Period_End >= L$4) * (Period_End <= L$5) * (IFERROR(SEARCH(L$1, Key_Gps),0)>0)))),0)} -> 0 | M7: {=IFERROR(ROWS(_xlfn.UNIQUE(_xlfn._xlws.FILTER(ID_Period_End,(Period_End >= M$4) * (Period_End <= M$5) * (IFERROR(SEARCH(M$1, Key_Gps),0)>0)))),0)} -> 0 | N7: =IFERROR(IF(E7/E8>1.25,"ERROR-REVIEW PAY SCHEDULE AND WEEKS!",IF(E7/E8>0.9,"Pay schedule is weekly.",IF(E7/E8<0.45,"Pay schedule is bimonthly.","Pay schedule is biweekly."))),"ERROR") -> ERROR | Q7: =IF(IFERROR(SEARCH("(",E7),0)=0,"",VALUE(SUBSTITUTE(RIGHT(E7,LEN(E7)-SEARCH("(",E7)),")",""))) | R7: =IF(U7="","",SUM(V7:AB7)-U7) -> 0 | S7: =IF($C7="","",IF(OR(IFERROR(SEARCH("min wage",LOWER($C7)),0)>0, IFERROR(SEARCH(" per ",LOWER($C7)),0)>0, IFERROR(SEARCH("penalt",LOWER($C7)),0)>0,IFERROR(SEARCH("total",LOWER($C7)),0)>0,IFERROR(SEARCH("interest",LOWER($C7)),0)>0,IFERROR(SEARCH("date",LOWER($C7)),0)>0,IFERROR(SEARCH("employee",LOWER($C7)),0)>0,IFERROR(SEARCH("average",LOWER($C7)),0)>0,IFERROR(SEARCH("median",LOWER($C7)),0)>0),"",1)) -> 1 | T7: =IF($S7<>1,"",IF(IFERROR(SEARCH("(",D7),0)=0,D7,VALUE(TRIM(LEFT(D7,SEARCH(" (",D7)))))) -> #NAME? | U7: =IF($S7<>1,"",IF(IFERROR(SEARCH("(",E7),0)=0,E7,VALUE(TRIM(LEFT(E7,SEARCH(" (",E7)))))) -> 0 | V7: =IF($S7<>1,"",IF(IFERROR(SEARCH("(",F7),0)=0,F7,VALUE(TRIM(LEFT(F7,SEARCH(" (",F7)))))) -> 0 | W7: =IF($S7<>1,"",IF(IFERROR(SEARCH("(",G7),0)=0,G7,VALUE(TRIM(LEFT(G7,SEARCH(" (",G7)))))) -> 0 | X7: =IF($S7<>1,"",IF(IFERROR(SEARCH("(",H7),0)=0,H7,VALUE(TRIM(LEFT(H7,SEARCH(" (",H7)))))) -> 0 | Y7: =IF($S7<>1,"",IF(IFERROR(SEARCH("(",I7),0)=0,I7,VALUE(TRIM(LEFT(I7,SEARCH(" (",I7)))))) -> 0 | Z7: =IF($S7<>1,"",IF(IFERROR(SEARCH("(",J7),0)=0,J7,VALUE(TRIM(LEFT(J7,SEARCH(" (",J7)))))) -> 0 | AA7: =IF($S7<>1,"",IF(IFERROR(SEARCH("(",K7),0)=0,K7,VALUE(TRIM(LEFT(K7,SEARCH(" (",K7)))))) -> 0 | ... AC7: =IF($S7<>1,"",IF(IFERROR(SEARCH("(",M7),0)=0,M7,VALUE(TRIM(LEFT(M7,SEARCH(" (",M7)))))) -> 0
C8: Weeks | D8: =ROUND((E8*ref!$B$4)/ref!$B$5,0) -> #NAME? | E8: {=SUMIFS(week,Date,">="&E$4,Date,"<="&E$5,Key_Gps,"*"&E$1&"*")} -> #NAME? | F8: {=SUMIFS(week,Date,">="&F$4,Date,"<="&F$5,Key_Gps,"*"&F$1&"*")} -> #NAME? | G8: {=SUMIFS(week,Date,">="&G$4,Date,"<="&G$5,Key_Gps,"*"&G$1&"*")} -> #NAME? | H8: {=SUMIFS(week,Date,">="&H$4,Date,"<="&H$5,Key_Gps,"*"&H$1&"*")} -> #NAME? | I8: {=SUMIFS(week,Date,">="&I$4,Date,"<="&I$5,Key_Gps,"*"&I$1&"*")} -> #NAME? | J8: {=SUMIFS(week,Date,">="&J$4,Date,"<="&J$5,Key_Gps,"*"&J$1&"*")} -> #NAME? | K8: {=SUMIFS(week,Date,">="&K$4,Date,"<="&K$5,Key_Gps,"*"&K$1&"*")} -> #NAME? | L8: {=SUMIFS(week,Date,">="&L$4,Date,"<="&L$5,Key_Gps,"*"&L$1&"*")} -> #NAME? | M8: {=SUMIFS(week,Date,">="&M$4,Date,"<="&M$5,Key_Gps,"*"&M$1&"*")} -> #NAME? | Q8: =IF(IFERROR(SEARCH("(",E8),0)=0,"",VALUE(SUBSTITUTE(RIGHT(E8,LEN(E8)-SEARCH("(",E8)),")",""))) | R8: =IF(U8="","",SUM(V8:AB8)-U8) -> #NAME? | S8: =IF($C8="","",IF(OR(IFERROR(SEARCH("min wage",LOWER($C8)),0)>0, IFERROR(SEARCH(" per ",LOWER($C8)),0)>0, IFERROR(SEARCH("penalt",LOWER($C8)),0)>0,IFERROR(SEARCH("total",LOWER($C8)),0)>0,IFERROR(SEARCH("interest",LOWER($C8)),0)>0,IFERROR(SEARCH("date",LOWER($C8)),0)>0,IFERROR(SEARCH("employee",LOWER($C8)),0)>0,IFERROR(SEARCH("average",LOWER($C8)),0)>0,IFERROR(SEARCH("median",LOWER($C8)),0)>0),"",1)) -> 1 | T8: =IF($S8<>1,"",IF(IFERROR(SEARCH("(",D8),0)=0,D8,VALUE(TRIM(LEFT(D8,SEARCH(" (",D8)))))) -> #NAME? | U8: =IF($S8<>1,"",IF(IFERROR(SEARCH("(",E8),0)=0,E8,VALUE(TRIM(LEFT(E8,SEARCH(" (",E8)))))) -> #NAME? | V8: =IF($S8<>1,"",IF(IFERROR(SEARCH("(",F8),0)=0,F8,VALUE(TRIM(LEFT(F8,SEARCH(" (",F8)))))) -> #NAME? | W8: =IF($S8<>1,"",IF(IFERROR(SEARCH("(",G8),0)=0,G8,VALUE(TRIM(LEFT(G8,SEARCH(" (",G8)))))) -> #NAME? | X8: =IF($S8<>1,"",IF(IFERROR(SEARCH("(",H8),0)=0,H8,VALUE(TRIM(LEFT(H8,SEARCH(" (",H8)))))) -> #NAME? | Y8: =IF($S8<>1,"",IF(IFERROR(SEARCH("(",I8),0)=0,I8,VALUE(TRIM(LEFT(I8,SEARCH(" (",I8)))))) -> #NAME? | Z8: =IF($S8<>1,"",IF(IFERROR(SEARCH("(",J8),0)=0,J8,VALUE(TRIM(LEFT(J8,SEARCH(" (",J8)))))) -> #NAME? | AA8: =IF($S8<>1,"",IF(IFERROR(SEARCH("(",K8),0)=0,K8,VALUE(TRIM(LEFT(K8,SEARCH(" (",K8)))))) -> #NAME? | ... AC8: =IF($S8<>1,"",IF(IFERROR(SEARCH("(",M8),0)=0,M8,VALUE(TRIM(LEFT(M8,SEARCH(" (",M8)))))) -> #NAME?
C9: Shifts | D9: =ROUND($E$10*D$8,0) -> #VALUE! | E9: {=COUNTIFS(Date,">="&E$4,Date,"<="&E$5,Key_Gps,"*"&E$1&"*")} -> #NAME? | F9: {=COUNTIFS(Date,">="&F$4,Date,"<="&F$5,Key_Gps,"*"&F$1&"*")} -> #NAME? | G9: {=COUNTIFS(Date,">="&G$4,Date,"<="&G$5,Key_Gps,"*"&G$1&"*")} -> #NAME? | H9: {=COUNTIFS(Date,">="&H$4,Date,"<="&H$5,Key_Gps,"*"&H$1&"*")} -> #NAME? | I9: {=COUNTIFS(Date,">="&I$4,Date,"<="&I$5,Key_Gps,"*"&I$1&"*")} -> #NAME? | J9: {=COUNTIFS(Date,">="&J$4,Date,"<="&J$5,Key_Gps,"*"&J$1&"*")} -> #NAME? | K9: {=COUNTIFS(Date,">="&K$4,Date,"<="&K$5,Key_Gps,"*"&K$1&"*")} -> #NAME? | L9: {=COUNTIFS(Date,">="&L$4,Date,"<="&L$5,Key_Gps,"*"&L$1&"*")} -> #NAME? | M9: {=COUNTIFS(Date,">="&M$4,Date,"<="&M$5,Key_Gps,"*"&M$1&"*")} -> #NAME? | Q9: =IF(IFERROR(SEARCH("(",E9),0)=0,"",VALUE(SUBSTITUTE(RIGHT(E9,LEN(E9)-SEARCH("(",E9)),")",""))) | R9: =IF(U9="","",SUM(V9:AB9)-U9) -> #NAME? | S9: =IF($C9="","",IF(OR(IFERROR(SEARCH("min wage",LOWER($C9)),0)>0, IFERROR(SEARCH(" per ",LOWER($C9)),0)>0, IFERROR(SEARCH("penalt",LOWER($C9)),0)>0,IFERROR(SEARCH("total",LOWER($C9)),0)>0,IFERROR(SEARCH("interest",LOWER($C9)),0)>0,IFERROR(SEARCH("date",LOWER($C9)),0)>0,IFERROR(SEARCH("employee",LOWER($C9)),0)>0,IFERROR(SEARCH("average",LOWER($C9)),0)>0,IFERROR(SEARCH("median",LOWER($C9)),0)>0),"",1)) -> 1 | T9: =IF($S9<>1,"",IF(IFERROR(SEARCH("(",D9),0)=0,D9,VALUE(TRIM(LEFT(D9,SEARCH(" (",D9)))))) -> #VALUE! | U9: =IF($S9<>1,"",IF(IFERROR(SEARCH("(",E9),0)=0,E9,VALUE(TRIM(LEFT(E9,SEARCH(" (",E9)))))) -> #NAME? | V9: =IF($S9<>1,"",IF(IFERROR(SEARCH("(",F9),0)=0,F9,VALUE(TRIM(LEFT(F9,SEARCH(" (",F9)))))) -> #NAME? | W9: =IF($S9<>1,"",IF(IFERROR(SEARCH("(",G9),0)=0,G9,VALUE(TRIM(LEFT(G9,SEARCH(" (",G9)))))) -> #NAME? | X9: =IF($S9<>1,"",IF(IFERROR(SEARCH("(",H9),0)=0,H9,VALUE(TRIM(LEFT(H9,SEARCH(" (",H9)))))) -> #NAME? | Y9: =IF($S9<>1,"",IF(IFERROR(SEARCH("(",I9),0)=0,I9,VALUE(TRIM(LEFT(I9,SEARCH(" (",I9)))))) -> #NAME? | Z9: =IF($S9<>1,"",IF(IFERROR(SEARCH("(",J9),0)=0,J9,VALUE(TRIM(LEFT(J9,SEARCH(" (",J9)))))) -> #NAME? | AA9: =IF($S9<>1,"",IF(IFERROR(SEARCH("(",K9),0)=0,K9,VALUE(TRIM(LEFT(K9,SEARCH(" (",K9)))))) -> #NAME? | ... AC9: =IF($S9<>1,"",IF(IFERROR(SEARCH("(",M9),0)=0,M9,VALUE(TRIM(LEFT(M9,SEARCH(" (",M9)))))) -> #NAME?
C10: Shifts per workweek | D10: =IFERROR(D9/D8,"-") -> - | E10: =IFERROR(E9/E8,"-") -> - | F10: =IFERROR(F9/F8,"-") -> - | G10: =IFERROR(G9/G8,"-") -> - | H10: =IFERROR(H9/H8,"-") -> - | I10: =IFERROR(I9/I8,"-") -> - | J10: =IFERROR(J9/J8,"-") -> - | K10: =IFERROR(K9/K8,"-") -> - | ... M10: =IFERROR(M9/M8,"-") -> - | Q10: =IF(IFERROR(SEARCH("(",E10),0)=0,"",VALUE(SUBSTITUTE(RIGHT(E10,LEN(E10)-SEARCH("(",E10)),")",""))) | R10: =IF(U10="","",SUM(V10:AB10)-U10) | S10: =IF($C10="","",IF(OR(IFERROR(SEARCH("min wage",LOWER($C10)),0)>0, IFERROR(SEARCH(" per ",LOWER($C10)),0)>0, IFERROR(SEARCH("penalt",LOWER($C10)),0)>0,IFERROR(SEARCH("total",LOWER($C10)),0)>0,IFERROR(SEARCH("interest",LOWER($C10)),0)>0,IFERROR(SEARCH("date",LOWER($C10)),0)>0,IFERROR(SEARCH("employee",LOWER($C10)),0)>0,IFERROR(SEARCH("average",LOWER($C10)),0)>0,IFERROR(SEARCH("median",LOWER($C10)),0)>0),"",1)) | T10: =IF($S10<>1,"",IF(IFERROR(SEARCH("(",D10),0)=0,D10,VALUE(TRIM(LEFT(D10,SEARCH(" (",D10)))))) | U10: =IF($S10<>1,"",IF(IFERROR(SEARCH("(",E10),0)=0,E10,VALUE(TRIM(LEFT(E10,SEARCH(" (",E10)))))) | V10: =IF($S10<>1,"",IF(IFERROR(SEARCH("(",F10),0)=0,F10,VALUE(TRIM(LEFT(F10,SEARCH(" (",F10)))))) | W10: =IF($S10<>1,"",IF(IFERROR(SEARCH("(",G10),0)=0,G10,VALUE(TRIM(LEFT(G10,SEARCH(" (",G10)))))) | X10: =IF($S10<>1,"",IF(IFERROR(SEARCH("(",H10),0)=0,H10,VALUE(TRIM(LEFT(H10,SEARCH(" (",H10)))))) | Y10: =IF($S10<>1,"",IF(IFERROR(SEARCH("(",I10),0)=0,I10,VALUE(TRIM(LEFT(I10,SEARCH(" (",I10)))))) | Z10: =IF($S10<>1,"",IF(IFERROR(SEARCH("(",J10),0)=0,J10,VALUE(TRIM(LEFT(J10,SEARCH(" (",J10)))))) | AA10: =IF($S10<>1,"",IF(IFERROR(SEARCH("(",K10),0)=0,K10,VALUE(TRIM(LEFT(K10,SEARCH(" (",K10)))))) | ... AC10: =IF($S10<>1,"",IF(IFERROR(SEARCH("(",M10),0)=0,M10,VALUE(TRIM(LEFT(M10,SEARCH(" (",M10))))))
C11: Average shift length | D11: =E11 -> - | E11: {=IFERROR(AVERAGEIFS(shift_hrs, Date,">="&E$4,Date,"<="&E$5,Key_Gps,"*"&E$1&"*"),"-")} -> - | F11: {=IFERROR(AVERAGEIFS(shift_hrs, Date,">="&F$4,Date,"<="&F$5,Key_Gps,"*"&F$1&"*"),"-")} -> - | G11: {=IFERROR(AVERAGEIFS(shift_hrs, Date,">="&G$4,Date,"<="&G$5,Key_Gps,"*"&G$1&"*"),"-")} -> - | H11: {=IFERROR(AVERAGEIFS(shift_hrs, Date,">="&H$4,Date,"<="&H$5,Key_Gps,"*"&H$1&"*"),"-")} -> - | I11: {=IFERROR(AVERAGEIFS(shift_hrs, Date,">="&I$4,Date,"<="&I$5,Key_Gps,"*"&I$1&"*"),"-")} -> - | J11: {=IFERROR(AVERAGEIFS(shift_hrs, Date,">="&J$4,Date,"<="&J$5,Key_Gps,"*"&J$1&"*"),"-")} -> - | K11: {=IFERROR(AVERAGEIFS(shift_hrs, Date,">="&K$4,Date,"<="&K$5,Key_Gps,"*"&K$1&"*"),"-")} -> - | L11: {=IFERROR(AVERAGEIFS(shift_hrs, Date,">="&L$4,Date,"<="&L$5,Key_Gps,"*"&L$1&"*"),"-")} -> - | M11: {=IFERROR(AVERAGEIFS(shift_hrs, Date,">="&M$4,Date,"<="&M$5,Key_Gps,"*"&M$1&"*"),"-")} -> - | Q11: =IF(IFERROR(SEARCH("(",E11),0)=0,"",VALUE(SUBSTITUTE(RIGHT(E11,LEN(E11)-SEARCH("(",E11)),")",""))) | R11: =IF(U11="","",SUM(V11:AB11)-U11) | S11: =IF($C11="","",IF(OR(IFERROR(SEARCH("min wage",LOWER($C11)),0)>0, IFERROR(SEARCH(" per ",LOWER($C11)),0)>0, IFERROR(SEARCH("penalt",LOWER($C11)),0)>0,IFERROR(SEARCH("total",LOWER($C11)),0)>0,IFERROR(SEARCH("interest",LOWER($C11)),0)>0,IFERROR(SEARCH("date",LOWER($C11)),0)>0,IFERROR(SEARCH("employee",LOWER($C11)),0)>0,IFERROR(SEARCH("average",LOWER($C11)),0)>0,IFERROR(SEARCH("median",LOWER($C11)),0)>0),"",1)) | T11: =IF($S11<>1,"",IF(IFERROR(SEARCH("(",D11),0)=0,D11,VALUE(TRIM(LEFT(D11,SEARCH(" (",D11)))))) | U11: =IF($S11<>1,"",IF(IFERROR(SEARCH("(",E11),0)=0,E11,VALUE(TRIM(LEFT(E11,SEARCH(" (",E11)))))) | V11: =IF($S11<>1,"",IF(IFERROR(SEARCH("(",F11),0)=0,F11,VALUE(TRIM(LEFT(F11,SEARCH(" (",F11)))))) | W11: =IF($S11<>1,"",IF(IFERROR(SEARCH("(",G11),0)=0,G11,VALUE(TRIM(LEFT(G11,SEARCH(" (",G11)))))) | X11: =IF($S11<>1,"",IF(IFERROR(SEARCH("(",H11),0)=0,H11,VALUE(TRIM(LEFT(H11,SEARCH(" (",H11)))))) | Y11: =IF($S11<>1,"",IF(IFERROR(SEARCH("(",I11),0)=0,I11,VALUE(TRIM(LEFT(I11,SEARCH(" (",I11)))))) | Z11: =IF($S11<>1,"",IF(IFERROR(SEARCH("(",J11),0)=0,J11,VALUE(TRIM(LEFT(J11,SEARCH(" (",J11)))))) | AA11: =IF($S11<>1,"",IF(IFERROR(SEARCH("(",K11),0)=0,K11,VALUE(TRIM(LEFT(K11,SEARCH(" (",K11)))))) | ... AC11: =IF($S11<>1,"",IF(IFERROR(SEARCH("(",M11),0)=0,M11,VALUE(TRIM(LEFT(M11,SEARCH(" (",M11))))))
C12: Median shift length | D12: =E12 -> - | E12: {=IFERROR(MEDIAN(IF((Date >= E$4) * (Date <= E$5) * (IFERROR(SEARCH(E$1, Key_Gps),0)>0),shift_hrs)),"-")} -> - | F12: {=IFERROR(MEDIAN(IF((Date >= F$4) * (Date <= F$5) * (IFERROR(SEARCH(F$1, Key_Gps),0)>0),shift_hrs)),"-")} -> - | G12: {=IFERROR(MEDIAN(IF((Date >= G$4) * (Date <= G$5) * (IFERROR(SEARCH(G$1, Key_Gps),0)>0),shift_hrs)),"-")} -> - | H12: {=IFERROR(MEDIAN(IF((Date >= H$4) * (Date <= H$5) * (IFERROR(SEARCH(H$1, Key_Gps),0)>0),shift_hrs)),"-")} -> - | I12: {=IFERROR(MEDIAN(IF((Date >= I$4) * (Date <= I$5) * (IFERROR(SEARCH(I$1, Key_Gps),0)>0),shift_hrs)),"-")} -> - | J12: {=IFERROR(MEDIAN(IF((Date >= J$4) * (Date <= J$5) * (IFERROR(SEARCH(J$1, Key_Gps),0)>0),shift_hrs)),"-")} -> - | K12: {=IFERROR(MEDIAN(IF((Date >= K$4) * (Date <= K$5) * (IFERROR(SEARCH(K$1, Key_Gps),0)>0),shift_hrs)),"-")} -> - | L12: {=IFERROR(MEDIAN(IF((Date >= L$4) * (Date <= L$5) * (IFERROR(SEARCH(L$1, Key_Gps),0)>0),shift_hrs)),"-")} -> - | M12: {=IFERROR(MEDIAN(IF((Date >= M$4) * (Date <= M$5) * (IFERROR(SEARCH(M$1, Key_Gps),0)>0),shift_hrs)),"-")} -> - | Q12: =IF(IFERROR(SEARCH("(",E12),0)=0,"",VALUE(SUBSTITUTE(RIGHT(E12,LEN(E12)-SEARCH("(",E12)),")",""))) | R12: =IF(U12="","",SUM(V12:AB12)-U12) | S12: =IF($C12="","",IF(OR(IFERROR(SEARCH("min wage",LOWER($C12)),0)>0, IFERROR(SEARCH(" per ",LOWER($C12)),0)>0, IFERROR(SEARCH("penalt",LOWER($C12)),0)>0,IFERROR(SEARCH("total",LOWER($C12)),0)>0,IFERROR(SEARCH("interest",LOWER($C12)),0)>0,IFERROR(SEARCH("date",LOWER($C12)),0)>0,IFERROR(SEARCH("employee",LOWER($C12)),0)>0,IFERROR(SEARCH("average",LOWER($C12)),0)>0,IFERROR(SEARCH("median",LOWER($C12)),0)>0),"",1)) | T12: =IF($S12<>1,"",IF(IFERROR(SEARCH("(",D12),0)=0,D12,VALUE(TRIM(LEFT(D12,SEARCH(" (",D12)))))) | U12: =IF($S12<>1,"",IF(IFERROR(SEARCH("(",E12),0)=0,E12,VALUE(TRIM(LEFT(E12,SEARCH(" (",E12)))))) | V12: =IF($S12<>1,"",IF(IFERROR(SEARCH("(",F12),0)=0,F12,VALUE(TRIM(LEFT(F12,SEARCH(" (",F12)))))) | W12: =IF($S12<>1,"",IF(IFERROR(SEARCH("(",G12),0)=0,G12,VALUE(TRIM(LEFT(G12,SEARCH(" (",G12)))))) | X12: =IF($S12<>1,"",IF(IFERROR(SEARCH("(",H12),0)=0,H12,VALUE(TRIM(LEFT(H12,SEARCH(" (",H12)))))) | Y12: =IF($S12<>1,"",IF(IFERROR(SEARCH("(",I12),0)=0,I12,VALUE(TRIM(LEFT(I12,SEARCH(" (",I12)))))) | Z12: =IF($S12<>1,"",IF(IFERROR(SEARCH("(",J12),0)=0,J12,VALUE(TRIM(LEFT(J12,SEARCH(" (",J12)))))) | AA12: =IF($S12<>1,"",IF(IFERROR(SEARCH("(",K12),0)=0,K12,VALUE(TRIM(LEFT(K12,SEARCH(" (",K12)))))) | ... AC12: =IF($S12<>1,"",IF(IFERROR(SEARCH("(",M12),0)=0,M12,VALUE(TRIM(LEFT(M12,SEARCH(" (",M12))))))
C13: Shifts >3.5 hrs | D13: =_xlfn.LET(_xlpm.denom,D$9,_xlpm.calc,ROUND($Q13*_xlpm.denom,0),_xlpm.perc,_xlpm.calc/_xlpm.denom,IFERROR(IF(_xlpm.calc<1000,_xlfn.CONCAT(_xlpm.calc," (",TEXT(_xlpm.perc,"0.0%"),")"),_xlfn.CONCAT(TEXT(_xlpm.calc,"0,000")," (",TEXT(_xlpm.perc,"0.0%"),")")),"-")) -> - | E13: {=_xlfn.LET(_xlpm.denom,E$9,_xlpm.calc,COUNTIFS(Date,">="&E$4,Date,"<="&E$5,shift_hrs,">"&$P13,Key_Gps,"*"&E$1&"*"),_xlpm.perc,_xlpm.calc/_xlpm.denom,IFERROR(IF(_xlpm.calc<1000,_xlfn.CONCAT(_xlpm.calc," (",TEXT(_xlpm.perc,"0.0%"),")"),_xlfn.CONCAT(TEXT(_xlpm.calc,"0,000")," (",TEXT(_xlpm.perc,"0.0%"),")")),"-"))} -> - | F13: {=_xlfn.LET(_xlpm.denom,F$9,_xlpm.calc,COUNTIFS(Date,">="&F$4,Date,"<="&F$5,shift_hrs,">"&$P13,Key_Gps,"*"&F$1&"*"),_xlpm.perc,_xlpm.calc/_xlpm.denom,IFERROR(IF(_xlpm.calc<1000,_xlfn.CONCAT(_xlpm.calc," (",TEXT(_xlpm.perc,"0.0%"),")"),_xlfn.CONCAT(TEXT(_xlpm.calc,"0,000")," (",TEXT(_xlpm.perc,"0.0%"),")")),"-"))} -> - | G13: {=_xlfn.LET(_xlpm.denom,G$9,_xlpm.calc,COUNTIFS(Date,">="&G$4,Date,"<="&G$5,shift_hrs,">"&$P13,Key_Gps,"*"&G$1&"*"),_xlpm.perc,_xlpm.calc/_xlpm.denom,IFERROR(IF(_xlpm.calc<1000,_xlfn.CONCAT(_xlpm.calc," (",TEXT(_xlpm.perc,"0.0%"),")"),_xlfn.CONCAT(TEXT(_xlpm.calc,"0,000")," (",TEXT(_xlpm.perc,"0.0%"),")")),"-"))} -> - | H13: {=_xlfn.LET(_xlpm.denom,H$9,_xlpm.calc,COUNTIFS(Date,">="&H$4,Date,"<="&H$5,shift_hrs,">"&$P13,Key_Gps,"*"&H$1&"*"),_xlpm.perc,_xlpm.calc/_xlpm.denom,IFERROR(IF(_xlpm.calc<1000,_xlfn.CONCAT(_xlpm.calc," (",TEXT(_xlpm.perc,"0.0%"),")"),_xlfn.CONCAT(TEXT(_xlpm.calc,"0,000")," (",TEXT(_xlpm.perc,"0.0%"),")")),"-"))} -> - | I13: {=_xlfn.LET(_xlpm.denom,I$9,_xlpm.calc,COUNTIFS(Date,">="&I$4,Date,"<="&I$5,shift_hrs,">"&$P13,Key_Gps,"*"&I$1&"*"),_xlpm.perc,_xlpm.calc/_xlpm.denom,IFERROR(IF(_xlpm.calc<1000,_xlfn.CONCAT(_xlpm.calc," (",TEXT(_xlpm.perc,"0.0%"),")"),_xlfn.CONCAT(TEXT(_xlpm.calc,"0,000")," (",TEXT(_xlpm.perc,"0.0%"),")")),"-"))} -> - | J13: {=_xlfn.LET(_xlpm.denom,J$9,_xlpm.calc,COUNTIFS(Date,">="&J$4,Date,"<="&J$5,shift_hrs,">"&$P13,Key_Gps,"*"&J$1&"*"),_xlpm.perc,_xlpm.calc/_xlpm.denom,IFERROR(IF(_xlpm.calc<1000,_xlfn.CONCAT(_xlpm.calc," (",TEXT(_xlpm.perc,"0.0%"),")"),_xlfn.CONCAT(TEXT(_xlpm.calc,"0,000")," (",TEXT(_xlpm.perc,"0.0%"),")")),"-"))} -> - | K13: {=_xlfn.LET(_xlpm.denom,K$9,_xlpm.calc,COUNTIFS(Date,">="&K$4,Date,"<="&K$5,shift_hrs,">"&$P13,Key_Gps,"*"&K$1&"*"),_xlpm.perc,_xlpm.calc/_xlpm.denom,IFERROR(IF(_xlpm.calc<1000,_xlfn.CONCAT(_xlpm.calc," (",TEXT(_xlpm.perc,"0.0%"),")"),_xlfn.CONCAT(TEXT(_xlpm.calc,"0,000")," (",TEXT(_xlpm.perc,"0.0%"),")")),"-"))} -> - | L13: {=_xlfn.LET(_xlpm.denom,L$9,_xlpm.calc,COUNTIFS(Date,">="&L$4,Date,"<="&L$5,shift_hrs,">"&$P13,Key_Gps,"*"&L$1&"*"),_xlpm.perc,_xlpm.calc/_xlpm.denom,IFERROR(IF(_xlpm.calc<1000,_xlfn.CONCAT(_xlpm.calc," (",TEXT(_xlpm.perc,"0.0%"),")"),_xlfn.CONCAT(TEXT(_xlpm.calc,"0,000")," (",TEXT(_xlpm.perc,"0.0%"),")")),"-"))} -> - | M13: {=_xlfn.LET(_xlpm.denom,M$9,_xlpm.calc,COUNTIFS(Date,">="&M$4,Date,"<="&M$5,shift_hrs,">"&$P13,Key_Gps,"*"&M$1&"*"),_xlpm.perc,_xlpm.calc/_xlpm.denom,IFERROR(IF(_xlpm.calc<1000,_xlfn.CONCAT(_xlpm.calc," (",TEXT(_xlpm.perc,"0.0%"),")"),_xlfn.CONCAT(TEXT(_xlpm.calc,"0,000")," (",TEXT(_xlpm.perc,"0.0%"),")")),"-"))} -> - | N13: Percent of all shifts. | P13: 3.5 | Q13: =IF(IFERROR(SEARCH("(",E13),0)=0,"",VALUE(SUBSTITUTE(RIGHT(E13,LEN(E13)-SEARCH("(",E13)),")",""))) | R13: =IF(U13="","",SUM(V13:AB13)-U13) -> #VALUE! | S13: =IF($C13="","",IF(OR(IFERROR(SEARCH("min wage",LOWER($C13)),0)>0, IFERROR(SEARCH(" per ",LOWER($C13)),0)>0, IFERROR(SEARCH("penalt",LOWER($C13)),0)>0,IFERROR(SEARCH("total",LOWER($C13)),0)>0,IFERROR(SEARCH("interest",LOWER($C13)),0)>0,IFERROR(SEARCH("date",LOWER($C13)),0)>0,IFERROR(SEARCH("employee",LOWER($C13)),0)>0,IFERROR(SEARCH("average",LOWER($C13)),0)>0,IFERROR(SEARCH("median",LOWER($C13)),0)>0),"",1)) -> 1 | T13: =IF($S13<>1,"",IF(IFERROR(SEARCH("(",D13),0)=0,D13,VALUE(TRIM(LEFT(D13,SEARCH(" (",D13)))))) -> - | U13: =IF($S13<>1,"",IF(IFERROR(SEARCH("(",E13),0)=0,E13,VALUE(TRIM(LEFT(E13,SEARCH(" (",E13)))))) -> - | V13: =IF($S13<>1,"",IF(IFERROR(SEARCH("(",F13),0)=0,F13,VALUE(TRIM(LEFT(F13,SEARCH(" (",F13)))))) -> - | W13: =IF($S13<>1,"",IF(IFERROR(SEARCH("(",G13),0)=0,G13,VALUE(TRIM(LEFT(G13,SEARCH(" (",G13)))))) -> - | X13: =IF($S13<>1,"",IF(IFERROR(SEARCH("(",H13),0)=0,H13,VALUE(TRIM(LEFT(H13,SEARCH(" (",H13)))))) -> - | Y13: =IF($S13<>1,"",IF(IFERROR(SEARCH("(",I13),0)=0,I13,VALUE(TRIM(LEFT(I13,SEARCH(" (",I13)))))) -> - | Z13: =IF($S13<>1,"",IF(IFERROR(SEARCH("(",J13),0)=0,J13,VALUE(TRIM(LEFT(J13,SEARCH(" (",J13)))))) -> - | AA13: =IF($S13<>1,"",IF(IFERROR(SEARCH("(",K13),0)=0,K13,VALUE(TRIM(LEFT(K13,SEARCH(" (",K13)))))) -> - | ... AC13: =IF($S13<>1,"",IF(IFERROR(SEARCH("(",M13),0)=0,M13,VALUE(TRIM(LEFT(M13,SEARCH(" (",M13)))))) -> -
C14: Shifts >5 hrs | D14: =_xlfn.LET(_xlpm.denom,D$9,_xlpm.calc,ROUND($Q14*_xlpm.denom,0),_xlpm.perc,_xlpm.calc/_xlpm.denom,IFERROR(IF(_xlpm.calc<1000,_xlfn.CONCAT(_xlpm.calc," (",TEXT(_xlpm.perc,"0.0%"),")"),_xlfn.CONCAT(TEXT(_xlpm.calc,"0,000")," (",TEXT(_xlpm.perc,"0.0%"),")")),"-")) -> - | E14: {=_xlfn.LET(_xlpm.denom,E$9,_xlpm.calc,COUNTIFS(Date,">="&E$4,Date,"<="&E$5,shift_hrs,">"&$P14,Key_Gps,"*"&E$1&"*"),_xlpm.perc,_xlpm.calc/_xlpm.denom,IFERROR(IF(_xlpm.calc<1000,_xlfn.CONCAT(_xlpm.calc," (",TEXT(_xlpm.perc,"0.0%"),")"),_xlfn.CONCAT(TEXT(_xlpm.calc,"0,000")," (",TEXT(_xlpm.perc,"0.0%"),")")),"-"))} -> - | F14: {=_xlfn.LET(_xlpm.denom,F$9,_xlpm.calc,COUNTIFS(Date,">="&F$4,Date,"<="&F$5,shift_hrs,">"&$P14,Key_Gps,"*"&F$1&"*"),_xlpm.perc,_xlpm.calc/_xlpm.denom,IFERROR(IF(_xlpm.calc<1000,_xlfn.CONCAT(_xlpm.calc," (",TEXT(_xlpm.perc,"0.0%"),")"),_xlfn.CONCAT(TEXT(_xlpm.calc,"0,000")," (",TEXT(_xlpm.perc,"0.0%"),")")),"-"))} -> - | G14: {=_xlfn.LET(_xlpm.denom,G$9,_xlpm.calc,COUNTIFS(Date,">="&G$4,Date,"<="&G$5,shift_hrs,">"&$P14,Key_Gps,"*"&G$1&"*"),_xlpm.perc,_xlpm.calc/_xlpm.denom,IFERROR(IF(_xlpm.calc<1000,_xlfn.CONCAT(_xlpm.calc," (",TEXT(_xlpm.perc,"0.0%"),")"),_xlfn.CONCAT(TEXT(_xlpm.calc,"0,000")," (",TEXT(_xlpm.perc,"0.0%"),")")),"-"))} -> - | H14: {=_xlfn.LET(_xlpm.denom,H$9,_xlpm.calc,COUNTIFS(Date,">="&H$4,Date,"<="&H$5,shift_hrs,">"&$P14,Key_Gps,"*"&H$1&"*"),_xlpm.perc,_xlpm.calc/_xlpm.denom,IFERROR(IF(_xlpm.calc<1000,_xlfn.CONCAT(_xlpm.calc," (",TEXT(_xlpm.perc,"0.0%"),")"),_xlfn.CONCAT(TEXT(_xlpm.calc,"0,000")," (",TEXT(_xlpm.perc,"0.0%"),")")),"-"))} -> - | I14: {=_xlfn.LET(_xlpm.denom,I$9,_xlpm.calc,COUNTIFS(Date,">="&I$4,Date,"<="&I$5,shift_hrs,">"&$P14,Key_Gps,"*"&I$1&"*"),_xlpm.perc,_xlpm.calc/_xlpm.denom,IFERROR(IF(_xlpm.calc<1000,_xlfn.CONCAT(_xlpm.calc," (",TEXT(_xlpm.perc,"0.0%"),")"),_xlfn.CONCAT(TEXT(_xlpm.calc,"0,000")," (",TEXT(_xlpm.perc,"0.0%"),")")),"-"))} -> - | J14: {=_xlfn.LET(_xlpm.denom,J$9,_xlpm.calc,COUNTIFS(Date,">="&J$4,Date,"<="&J$5,shift_hrs,">"&$P14,Key_Gps,"*"&J$1&"*"),_xlpm.perc,_xlpm.calc/_xlpm.denom,IFERROR(IF(_xlpm.calc<1000,_xlfn.CONCAT(_xlpm.calc," (",TEXT(_xlpm.perc,"0.0%"),")"),_xlfn.CONCAT(TEXT(_xlpm.calc,"0,000")," (",TEXT(_xlpm.perc,"0.0%"),")")),"-"))} -> - | K14: {=_xlfn.LET(_xlpm.denom,K$9,_xlpm.calc,COUNTIFS(Date,">="&K$4,Date,"<="&K$5,shift_hrs,">"&$P14,Key_Gps,"*"&K$1&"*"),_xlpm.perc,_xlpm.calc/_xlpm.denom,IFERROR(IF(_xlpm.calc<1000,_xlfn.CONCAT(_xlpm.calc," (",TEXT(_xlpm.perc,"0.0%"),")"),_xlfn.CONCAT(TEXT(_xlpm.calc,"0,000")," (",TEXT(_xlpm.perc,"0.0%"),")")),"-"))} -> - | L14: {=_xlfn.LET(_xlpm.denom,L$9,_xlpm.calc,COUNTIFS(Date,">="&L$4,Date,"<="&L$5,shift_hrs,">"&$P14,Key_Gps,"*"&L$1&"*"),_xlpm.perc,_xlpm.calc/_xlpm.denom,IFERROR(IF(_xlpm.calc<1000,_xlfn.CONCAT(_xlpm.calc," (",TEXT(_xlpm.perc,"0.0%"),")"),_xlfn.CONCAT(TEXT(_xlpm.calc,"0,000")," (",TEXT(_xlpm.perc,"0.0%"),")")),"-"))} -> - | M14: {=_xlfn.LET(_xlpm.denom,M$9,_xlpm.calc,COUNTIFS(Date,">="&M$4,Date,"<="&M$5,shift_hrs,">"&$P14,Key_Gps,"*"&M$1&"*"),_xlpm.perc,_xlpm.calc/_xlpm.denom,IFERROR(IF(_xlpm.calc<1000,_xlfn.CONCAT(_xlpm.calc," (",TEXT(_xlpm.perc,"0.0%"),")"),_xlfn.CONCAT(TEXT(_xlpm.calc,"0,000")," (",TEXT(_xlpm.perc,"0.0%"),")")),"-"))} -> - | N14: Percent of all shifts. | P14: 5 | Q14: =IF(IFERROR(SEARCH("(",E14),0)=0,"",VALUE(SUBSTITUTE(RIGHT(E14,LEN(E14)-SEARCH("(",E14)),")",""))) | R14: =IF(U14="","",SUM(V14:AB14)-U14) -> #VALUE! | S14: =IF($C14="","",IF(OR(IFERROR(SEARCH("min wage",LOWER($C14)),0)>0, IFERROR(SEARCH(" per ",LOWER($C14)),0)>0, IFERROR(SEARCH("penalt",LOWER($C14)),0)>0,IFERROR(SEARCH("total",LOWER($C14)),0)>0,IFERROR(SEARCH("interest",LOWER($C14)),0)>0,IFERROR(SEARCH("date",LOWER($C14)),0)>0,IFERROR(SEARCH("employee",LOWER($C14)),0)>0,IFERROR(SEARCH("average",LOWER($C14)),0)>0,IFERROR(SEARCH("median",LOWER($C14)),0)>0),"",1)) -> 1 | T14: =IF($S14<>1,"",IF(IFERROR(SEARCH("(",D14),0)=0,D14,VALUE(TRIM(LEFT(D14,SEARCH(" (",D14)))))) -> - | U14: =IF($S14<>1,"",IF(IFERROR(SEARCH("(",E14),0)=0,E14,VALUE(TRIM(LEFT(E14,SEARCH(" (",E14)))))) -> - | V14: =IF($S14<>1,"",IF(IFERROR(SEARCH("(",F14),0)=0,F14,VALUE(TRIM(LEFT(F14,SEARCH(" (",F14)))))) -> - | W14: =IF($S14<>1,"",IF(IFERROR(SEARCH("(",G14),0)=0,G14,VALUE(TRIM(LEFT(G14,SEARCH(" (",G14)))))) -> - | X14: =IF($S14<>1,"",IF(IFERROR(SEARCH("(",H14),0)=0,H14,VALUE(TRIM(LEFT(H14,SEARCH(" (",H14)))))) -> - | Y14: =IF($S14<>1,"",IF(IFERROR(SEARCH("(",I14),0)=0,I14,VALUE(TRIM(LEFT(I14,SEARCH(" (",I14)))))) -> - | Z14: =IF($S14<>1,"",IF(IFERROR(SEARCH("(",J14),0)=0,J14,VALUE(TRIM(LEFT(J14,SEARCH(" (",J14)))))) -> - | AA14: =IF($S14<>1,"",IF(IFERROR(SEARCH("(",K14),0)=0,K14,VALUE(TRIM(LEFT(K14,SEARCH(" (",K14)))))) -> - | ... AC14: =IF($S14<>1,"",IF(IFERROR(SEARCH("(",M14),0)=0,M14,VALUE(TRIM(LEFT(M14,SEARCH(" (",M14)))))) -> -
